Workbook

Sheet Тест кейсы API
A1: Модуль | B1: ID | C1: Приоритет | D1: Название тест кейса | E1: Описание | F1: Предусловия | G1: Шаги воспроизведения | H1: ОР | I1: Скринкаст/скриншот | J1: Ссылка на БР | K1: Статус проверки | L1: Комментарии
A2: whom_we_helped | B2: API_w_w_hlpd_1 | C2: Высокий | D2: Успешное получение списка опубликованных завершенных запросов при запросе на эндпоинт whom_we_helped/ | E2: Проверить, что по умолчанию эндпоинт возвращает успешный ответ с корректной структурой данных и пагинацией | F2: 1.Открыто приложение Postman 2.Ввести адрес тестового стенда: pl.rassokha.pro:8000/api/v1 3.API доступен и авторизация не требуется для GET-запроса | G2: 1. Создать GET запрос на эндпоинт whom_we_helped/ 2. Отправить запрос | H2: Ошибки в структуре ответа нет "Ответ приходит без ошибок 200 ок { "count": integer, "next": "string($uri)", "previous": "string($uri)", "results": [ { "images": "string($uri)", "text": "string" } ] } | K2: Passed
A3: whom_we_helped | B3: API_w_w_hlpd_2 | C3: Высокий | D3: Корректная работа пагинации - переход по страницам при запросе на эндпоинт whom_we_helped/ | E3: Проверить, что параметр page корректно разделяет результаты на страницы | F3: 1.Открыто приложение Postman 2.Открыт тестовый стенд: pl.rassokha.pro:8000/api/v1 3.API доступен и авторизация не требуется для GET-запроса | G3: 1. Создать GET запрос на эндпоинт whom_we_helped/ 2. Во вкладке params вставить key: page 3. Во вкладке params вставить value: integer, где номер страницы не превышает существующие количество страниц 4. Отправить запрос | H3: Ошибки в структуре ответа нет "Ответ приходит без ошибок 200 ок { "count": integer, "next": "string($uri)", "previous": "string($uri)", "results": [ { "images": "string($uri)", "text": "string" } ] } | K3: Passed
A4: whom_we_helped | B4: API_w_w_hlpd_3 | C4: Высокий | D4: Проверка ответа при отсутствии данных(пустой параметр)при запросе на эндпоинт whom_we_helped/ | E4: Проверить поведение API припустом вводе | F4: 1.Открыто приложение Postman 2.Открыт тестовый стенд: pl.rassokha.pro:8000/api/v1 3.API доступен и авторизация не требуется для GET-запроса | G4: 1. Создать GET запрос на эндпоинт whom_we_helped/ 2. Во вкладке params вставить key: page 3.Отправить запрос | H4: Ошибки в структуре ответа нет "Ответ приходит без ошибок 200 ок { "count": integer, "next": "string($uri)", "previous": "string($uri)", "results": [ { "images": "string($uri)", "text": "string" } ] } | K4: Passed
A5: whom_we_helped | B5: API_w_w_hlpd_4 | C5: Высокий | D5: Проверка запроса с неверным HTTP-методом OPTIONS при запросе на эндпоинт whom_we_helped/ | E5: Отправить запрос с методом OPTIONS https://pl.rassokha.pro:8000/api/v1/whom_we_helped/ | F5: 1.Открыто приложение Postman 2.Открыт тестовый стенд: pl.rassokha.pro:8000/api/v1 3.API доступен и авторизация не требуется для OPTIONS-запроса | G5: 1. Создать OPTIONS запрос на эндпоинт whom_we_helped/ 2. Отправить запрос | H5: 405 Method Not Allowed { "detail": "Метод \"OPTIONS\" не разрешен." } | K5: Skipped
A6: whom_we_helped | B6: API_w_w_hlpd_5 | C6: Высокий | D6: Получение отчета со всеми заполненными полями при запросе на эндпоинт whom_we_helped/ | E6: Проверить, что в ответе присутствуют посты, у которых заполнены все обязательные и необязательные поля (например, id, image_url, title, description,minLength), и их значения соответствуют ожидаемым типам данных | F6: 1.Открыто приложение Postman 2.Открыт тестовый стенд: pl.rassokha.pro:8000/api/v1 3.API доступен и авторизация не требуется для GET-запроса | G6: 1. Создать GET запрос на эндпоинт whom_we_helped/ 2. Отправить запрос | H6: Ошибки в структуре ответа нет "Ответ приходит без ошибок 200 ок | K6: Skipped
A7: whom_we_helped | B7: API_w_w_hlpd_6 | C7: Высокий | D7: Получение поста только с описанием (без фотографии) при запросе на эндпоинт whom_we_helped/ | E7: Проверить, как система обрабатывает пост, у которого есть текстовое описание, но отсутствует фотография | F7: 1.Открыто приложение Postman 2.Открыт тестовый стенд: pl.rassokha.pro:8000/api/v1 3.API доступен и авторизация не требуется для GET-запроса | G7: 1. Создать GET запрос на эндпоинт whom_we_helped/ 2. Отправить запрос | H7: Ошибки в структуре ответа нет "Ответ приходит без ошибок 200 ок | K7: Skipped
A8: whom_we_helped | B8: API_w_w_hlpd_7 | C8: Высокий | D8: Получение поста с описанием на иностранном языке при запросе на эндпоинт whom_we_helped/ | E8: Проверить, что отчеты, содержащие в описании символы иностранных языков (например, English, 中文), корректно отображаются в ответе API без искажений (проблем с кодировкой). | F8: 1.Открыто приложение Postman 2.Открыт тестовый стенд: pl.rassokha.pro:8000/api/v1 3.API доступен и авторизация не требуется для GET-запроса | G8: 1. Создать GET запрос на эндпоинт whom_we_helped/ 2.Отправить запрос | H8: Ошибки в структуре ответа нет "Ответ приходит без ошибок 200 ок | K8: Skipped
A9: whom_we_helped | B9: API_w_w_hlpd_8 | C9: Высокий | D9: Проверка структуры данных одного поста при запросе на эндпоинт whom_we_helped/ | E9: Проверить, что каждый элемент в массиве содержит ожидаемый набор полей | F9: 1.Открыто приложение Postman 2.Открыт тестовый стенд: pl.rassokha.pro:8000/api/v1 3.API доступен и авторизация не требуется для GET-запроса | G9: 1. Создать GET запрос на эндпоинт whom_we_helped/ 2.Отправить запрос | H9: Ошибки в структуре ответа нет "Ответ приходит без ошибок 200 ок | K9: Skipped
A10: whom_we_helped | B10: API_w_w_hlpd_9 | C10: Высокий | D10: Проверка значения по умолчания для параметра page при запросе на эндпоинт whom_we_helped/ | E10: Убедиться, что запросы /api/v1/whom_we_helped/ и /api/v1/whom_we_helped/?page=1 возвращают идентичный результат | F10: 1.Открыто приложение Postman 2.Открыт тестовый стенд: pl.rassokha.pro:8000/api/v1 3.API доступен и авторизация не требуется для GET-запроса | G10: 1. Отправить GET /api/v1/whom_we_helped/ 2. Отправить GET /api/v1/whom_we_helped/?page=1 3. Сравнить ответы | H10: Ошибки в структуре ответа нет "Ответ приходит без ошибок 200 ок { "count": integer, "next": "string($uri)", "previous": "string($uri)", "results": [ { "images": "string($uri)", "text": "string" } ] } | K10: Blocked
A11: whom_we_helped | B11: API_w_w_hlpd_10 | C11: Высокий | D11: Проверка запроса с буквенным типом параметра page при запросе на эндпоинт whom_we_helped/ | E11: Отправить запрос с параметром page, имеющим буквенное значение (например, page=abc). | F11: 1.Открыто приложение Postman 2.Открыт тестовый стенд: pl.rassokha.pro:8000/api/v1 3.API доступен и авторизация не требуется для GET-запроса | G11: 1. Создать GET запрос на эндпоинт whom_we_helped/ 2. Во вкладке params вставить key: page 3. Во вкладке params вставить value: abc 2.Отправить запрос | H11: 404 Not Found Body ответа: { "detail": "Неправильная страница" } | K11: Skipped
A12: whom_we_helped | B12: API_w_w_hlpd_11 | C12: Высокий | D12: Обработка запроса с отрицательным значением параметра page при запросе на эндпоинт whom_we_helped/ | E12: Отправить запрос с page=-1 | F12: 1.Открыто приложение Postman 2.Открыт тестовый стенд: pl.rassokha.pro:8000/api/v1 3.API доступен и авторизация не требуется для GET-запроса | G12: 1. Создать GET запрос на эндпоинт whom_we_helped/ 2. Во вкладке params вставить key: page 3. Во вкладке params вставить value: -1 2.Отправить запрос | H12: 404 Not Found Body ответа: { "detail": "Неправильная страница" } | K12: Passed
A13: whom_we_helped | B13: API_w_w_hlpd_12 | C13: Высокий | D13: Проверка обработки запроса со спецсимволами при запросе на эндпоинт whom_we_helped/ | E13: Отправить запрос с page=+2 | F13: 1.Открыто приложение Postman 2.Открыт тестовый стенд: pl.rassokha.pro:8000/api/v1 3.API доступен и авторизация не требуется для GET-запроса | G13: 1. Создать GET запрос на эндпоинт whom_we_helped/ 2. Во вкладке params вставить key: page 3. Во вкладке params вставить value: +2 2.Отправить запрос | H13: 404 Not Found Body ответа: { "detail": "Неправильная страница" } | K13: Skipped
... A64: they_need_help_too | B64: API_they_nd_hlp_2 | C64: Средний | D64: Получение списка семей которым нужна помощь неверным HTTP-методом | E64: Отправить запрос с методом POST https://pl.rassokha.pro:8000/api/v1/they_need_help_too/ | F64: 1.Открыто приложение Postman 2.Открыт тестовый стенд: pl.rassokha.pro:8000/api/v1 3.API доступен и авторизация не требуется для POST-запроса | G64: 1. Создать POST запрос на эндпоинт they_need_help_too/ 2. Отправить запрос | H64: 405 Method Not Allowed { "detail": "Метод \"POST\" не разрешен." } | K64: Passed
A65: they_need_help_too | B65: API_they_nd_hlp_3 | C65: Средний | D65: Успешное получение существующей семьи которой нужна помощь | E65: Отправить запрос с методом GET https://pl.rassokha.pro:8000/api/v1/they_need_help_too/ | F65: 1. Открыто приложение Postman 2. Используется тестовый стенд pl.rassokha.pro:8000/api/v1 3.API доступен и авторизация не требуется для GET-запроса | G65: 1. Создать GET запрос на эндпоинт they_need_help_too/{id}/ где {id} - существующий идентификатор семьи 2.Отправить запрос | H65: Возвращается код 200 OK Тело ответа: [ { "id": integer, "family_name": "string", "image": "string($uri)" } ] | I65: they_need_help_too_bg1.png | J65: QA_Pomogi_2_39_Тестовая документация | K65: Blocked
A66: team_member | B66: API_tm_mmbr_1 | C66: Средний | D66: Успешное получение списка членов команды | E66: Отправить запрос с методом GET https://pl.rassokha.pro:8000/api/v1/team_member/ | F66: 1. Открыто приложение Postman 2. Используется тестовый стенд pl.rassokha.pro:8000/api/v1 3.API доступен и авторизация не требуется для GET-запроса | G66: 1. Создать GET запрос на эндпоинт team_member/ 2.Отправить запрос | H66: Возвращается код 200 OK [ { "name": "string", "member_title": "string", "photo": "string($uri)" } ] | K66: Passed
A67: team_member | B67: API_tm_mmbr_2 | C67: Средний | D67: Получение списка членов команды недопустимым HTTP-методом | E67: Отправить запрос с методом POST https://pl.rassokha.pro:8000/api/v1/team_member/ | F67: 1.Открыто приложение Postman 2.Открыт тестовый стенд: pl.rassokha.pro:8000/api/v1 3.API доступен и авторизация не требуется для POST-запроса | G67: 1. Создать POST запрос на эндпоинт team_member/ 2. Отправить запрос | H67: 405 Method Not Allowed { "detail": "Метод \"POST\" не разрешен." } | K67: Passed
A68: team_member | B68: API_tm_mmbr_3 | C68: Средний | D68: Успешное получение существующего члена команды | E68: Отправить запрос с методом GET https://pl.rassokha.pro:8000/api/v1/team_member/{id}/ | F68: 1. Открыто приложение Postman 2. Используется тестовый стенд pl.rassokha.pro:8000/api/v1 3.API доступен и авторизация не требуется для GET-запроса | G68: 1. Создать GET запрос на эндпоинт team_member/{id}/ где {id} - существующий идентификатор члена команды 2.Отправить запрос | H68: Возвращается код 200 OK [ { "name": "string", "member_title": "string", "photo": "string($uri)" } ] | K68: Passed
A69: team_member | B69: API_tm_mmbr_4 | C69: Средний | D69: Попытка получения несуществующего члена команды | E69: Отправить запрос с методом GET https://pl.rassokha.pro:8000/api/v1/team_member/{id}/ | F69: 1. Открыто приложение Postman 2. Используется тестовый стенд pl.rassokha.pro:8000/api/v1 3. Убедиться, что челена команды {id} НЕ существует | G69: 1. Создать GET запрос на эндпоинт team_member/{id}/ 2.Отправить запрос | H69: Возвращается код 404 Not Found Тело ответа: { "detail": "No TeamMember matches the given query." } | K69: Passed
A70: team_member | B70: API_tm_mmbr_5 | C70: Средний | D70: Попытка получения члена команды с нечисловым ID | E70: Отправить запрос с методом GET https://pl.rassokha.pro:8000/api/v1/team_member/{id}/ | F70: 1. Открыто приложение Postman 2. Используется тестовый стенд pl.rassokha.pro:8000/api/v1 3.API доступен и авторизация не требуется для GET-запроса | G70: 1. Создать GET запрос на эндпоинт team_member/abc 2.Отправить запрос | H70: Возвращается код 404 Not Found Тело ответа: { "detail": "Страница не найдена." } | K70: Passed
A71: team_member | B71: API_tm_mmbr_6 | C71: Средний | D71: Получение существующего члена команды недопустимым HTTP-методом | E71: Отправить запрос с методом POST https://pl.rassokha.pro:8000/api/v1/team_member/{id}/ | F71: 1.Открыто приложение Postman 2.Открыт тестовый стенд: pl.rassokha.pro:8000/api/v1 3.API доступен и авторизация не требуется для POST-запроса | G71: 1. Создать POST запрос на эндпоинт team_member/{id}/ где {id} - существующий идентификатор члена команды 2.Отправить запрос | H71: 405 Method Not Allowed { "detail": "Метод \"POST\" не разрешен." } | K71: Passed
A72: social_links | B72: API_scl_lnks_1 | C72: Средний | D72: Успешное получение списка существующих социальных ссылок | E72: Отправить запрос с методом GET https://pl.rassokha.pro:8000/api/v1/social_links/ | F72: 1. Открыто приложение Postman 2. Используется тестовый стенд pl.rassokha.pro:8000/api/v1 3.API доступен и авторизация не требуется для GET-запроса | G72: 1. Создать GET запрос на эндпоинт social_links/ 2.Отправить запрос | H72: Возвращается код 200 OK Тело ответа: [ { "label": "string", "link": "string($uri)", "icon": "string", "slug": "string" } ] | K72: Passed
A73: social_links | B73: API_scl_lnks_2 | C73: Средний | D73: Получение списка существующих социальных ссылок неверным HTTP-методом | E73: Отправить запрос с методом POST https://pl.rassokha.pro:8000/api/v1/social_links/ | F73: 1.Открыто приложение Postman 2.Открыт тестовый стенд: pl.rassokha.pro:8000/api/v1 3.API доступен и авторизация не требуется для POST-запроса | G73: 1. Создать POST запрос на эндпоинт social_links/ 2.Отправить запрос | H73: Возвращается код 405 Method Not Allowed { "detail": "Метод \"POST\" не разрешен." } | K73: Passed
A74: social_links | B74: API_scl_lnks_3 | C74: Средний | D74: Успешное получение существующей социальной ссылки | E74: Отправить запрос с методом GET https://pl.rassokha.pro:8000/api/v1/social_links/{slug}/ | F74: 1. Открыто приложение Postman 2. Используется тестовый стенд pl.rassokha.pro:8000/api/v1 3.API доступен и авторизация не требуется для GET-запроса | G74: 1. Создать GET запрос на эндпоинт social_links/{slug}/ где {slug} - существующая социальная ссылка 2.Отправить запрос | H74: Возвращается код 200 OK Тело ответа: [ { "label": "string", "link": "string($uri)", "icon": "string", "slug": "string" } ] | K74: Passed
A75: social_links | B75: API_scl_lnks_4 | C75: Средний | D75: Попытка получение не существующей социальной ссылки | E75: Отправить запрос с методом GET https://pl.rassokha.pro:8000/api/v1/social_links/{slug}/ | F75: 1. Открыто приложение Postman 2. Используется тестовый стенд pl.rassokha.pro:8000/api/v1 3.Убедиться, что социальной ссылки {slug} НЕ существует | G75: 1. Создать GET запрос на эндпоинт social_links/{slug}/ 2.Отправить запрос | H75: Возвращается код 404 Not Found Тело ответа: { "detail": "No SocialLink matches the given query." } | K75: Passed
A76: social_links | B76: API_scl_lnks_5 | C76: Средний | D76: Попытка получения социальной ссылки c нестрочным SLUG | E76: Отправить запрос с методом GET https://pl.rassokha.pro:8000/api/v1/social_links/{slug}/ | F76: 1. Открыто приложение Postman 2. Используется тестовый стенд pl.rassokha.pro:8000/api/v1 3.API доступен и авторизация не требуется для GET-запроса | G76: 1. Создать GET запрос на эндпоинт social_links/12/ 2.Отправить запрос | H76: Возвращается код 404 Not Found Тело ответа: { "detail": "No SocialLink matches the given query." } | K76: Passed
A77: social_links | B77: API_scl_lnks_6 | C77: Средний | D77: Получение существующей социальной ссылки неверным HTTP-методом | E77: Отправить запрос с методом POST https://pl.rassokha.pro:8000/api/v1/social_links/{slug}/ | F77: 1. Открыто приложение Postman 2. Используется тестовый стенд pl.rassokha.pro:8000/api/v1 3.API доступен и авторизация не требуется для POST-запроса | G77: 1. Создать POST запрос на эндпоинт social_links/{slug}/ 2.Отправить запрос | H77: 405 Method Not Allowed { "detail": "Метод \"POST\" не разрешен." } | K77: Passed
... A80: family_applications_list | B80: API_fml_pplctns_lst_3 | C80: Высокий | D80: Получение списка заявок и списка городов заявок: с указанием неверного метода | E80: Отправить запрос с методом POST https://pl.rassokha.pro:8000/api/v1/family_applications_list/ | F80: 1. Открыто приложение Postman 2. Используется тестовый стенд pl.rassokha.pro:8000/api/v1 3.API доступен и авторизация не требуется для POST-запроса | G80: 1. Создать POST запрос на эндпоинт /family_applications_list/ 2. Во вкладке Params ввести: key: "limit", value: 5 key: "offset", value: 5 3. Отправить запрос | H80: 405 Method Not Allowed { "detail": "Метод \"POST\" не разрешен." } | K80: Passed
A81: family_applications_list | B81: API_fml_pplctns_lst_4 | C81: Высокий | D81: Получение списка заявок и списка городов заявок: параметры = "string" | E81: Отправить запрос с методом GET https://pl.rassokha.pro:8000/api/v1/family_applications_list/ | F81: 1. Открыто приложение Postman 2. Используется тестовый стенд pl.rassokha.pro:8000/api/v1 3.API доступен и авторизация не требуется для GET-запроса | G81: 1. Создать GET запрос на эндпоинт /family_applications_list/ 2. Во вкладке Params ввести: key: "limit", value: "12" key: "offset", value: "12" 3. Отправить запрос | H81: 400 Bad Request | I81: API_fml_pplctns_lst_2.png | J81: QA_Pomogi_2_39_Тестовая документация | K81: Failed
A82: family_applications_list | B82: API_fml_pplctns_lst_5 | C82: Высокий | D82: Получение списка заявок и списка городов заявок: параметры = null | E82: Отправить запрос с методом GET https://pl.rassokha.pro:8000/api/v1/family_applications_list/ | F82: 1. Открыто приложение Postman 2. Используется тестовый стенд pl.rassokha.pro:8000/api/v1 3.API доступен и авторизация не требуется для GET-запроса | G82: 1. Создать GET запрос на эндпоинт /family_applications_list/ 2. Во вкладке Params ввести: key: "limit", value: null key: "offset", value: null 3. Отправить запрос | H82: 200 Ок { "count": integer, "next": "string($uri)", "previous": "string($uri)", "results": [ { "id": integer, "city": "string", "full_name": "string", "status": "string" } ] } | K82: Passed
A83: family_applications_list | B83: API_fml_pplctns_lst_6 | C83: Высокий | D83: Получение списка заявок и списка городов заявок: параметры = дробь | E83: Отправить запрос с методом GET https://pl.rassokha.pro:8000/api/v1/family_applications_list/ | F83: 1. Открыто приложение Postman 2. Используется тестовый стенд pl.rassokha.pro:8000/api/v1 3.API доступен и авторизация не требуется для GET-запроса | G83: 1. Создать GET запрос на эндпоинт /family_applications_list/ 2. Во вкладке Params ввести: key: "limit", value: 2.2 key: "offset", value: 2.2 3. Отправить запрос | H83: 400 Bad Request | I83: API_fml_pplctns_lst_1.png | J83: QA_Pomogi_2_39_Тестовая документация | K83: Failed
A84: family_applications_list | B84: API_fml_pplctns_lst_7 | C84: Высокий | D84: Получение списка заявок и списка городов заявок: с передачей параметра "limit" со значением, превышающим количество созданных заявок | E84: Отправить запрос с методом GET https://pl.rassokha.pro:8000/api/v1/family_applications_list/ | F84: 1. Открыто приложение Postman 2. Используется тестовый стенд pl.rassokha.pro:8000/api/v1 3.API доступен и авторизация не требуется для GET-запроса | G84: 1. Создать GET запрос на эндпоинт /family_applications_list/ 2. Во вкладке Params ввести: key: "limit", value: integer (где integer - целое число, превышающее количество созданных заявок) 3. Отправить запрос | H84: Список = количеству созданных заявок без каких-либо добавлений 200 Ок { "count": integer, "next": "string($uri)", "previous": "string($uri)", "results": [ { "id": integer, "city": "string", "full_name": "string", "status": "string" } ] } | K84: Passed
A85: family_applications_list | B85: API_fml_pplctns_lst_8 | C85: Высокий | D85: Получение списка заявок и списка городов заявок: с передачей параметра "offset" со значением, превышающим количество созданных заявок | E85: Отправить запрос с методом GET https://pl.rassokha.pro:8000/api/v1/family_applications_list/ | F85: 1. Открыто приложение Postman 2. Используется тестовый стенд pl.rassokha.pro:8000/api/v1 3.API доступен и авторизация не требуется для GET-запроса | G85: 1. Создать GET запрос на эндпоинт /family_applications_list/ 2. Во вкладке Params ввести: key: "offset", value: integer (где integer - целое число, превышающее количество созданных заявок) 3. Отправить запрос | H85: 200 Ок { "count": integer, "next": "null, "previous": "string($uri)", "results": [] } | K85: Passed
A86: family_applications_list | B86: API_fml_pplctns_lst_9 | C86: Высокий | D86: Получение списка городов заявок | E86: Отправить запрос с методом GET https://pl.rassokha.pro:8000/api/v1/family_applications_list/cities/ | F86: 1. Открыто приложение Postman 2. Используется тестовый стенд pl.rassokha.pro:8000/api/v1 3.API доступен и авторизация не требуется для GET-запроса | G86: 1.Создать GET запрос на эндпоинт /family_applications_list/cities/ 2. Отправить запрос | H86: список городов, указанных при регистрации заявки на оказание помощи в алфавитном порядке 200 ОК [ "string", "string" ] | I86: API_fml_pplctns_lst_bg_3.png | J86: QA_Pomogi_2_39_Тестовая документация | K86: Passed
A87: family_applications_list | B87: API_fml_pplctns_lst_10 | C87: Высокий | D87: Получение списка городов заявок: с передачей параметров | E87: Отправить запрос с методом GET https://pl.rassokha.pro:8000/api/v1/family_applications_list/cities/ | F87: 1. Открыто приложение Postman 2. Используется тестовый стенд pl.rassokha.pro:8000/api/v1 3.API доступен и авторизация не требуется для GET-запроса | G87: 1. Создать GET запрос на эндпоинт /family_applications_list/cities/ 2. Во вкладке Params ввести: key: "limit", value: 5 key: "offset", value: 5 3. Отправить запрос | H87: список из 5 городов в алфавитном порядке, начиная в шестого по порядку (указанные при регистрации заявки на оказание помощи) 200 ОК [ "string", "string" ] | J87: QA_Pomogi_2_39_Тестовая документация | K87: Blocked
A88: family_applications_list | B88: API_fml_pplctns_lst_11 | C88: Высокий | D88: Получение списка городов заявок: с указанием неверного метода | E88: Отправить запрос с методом POST https://pl.rassokha.pro:8000/api/v1/family_applications_list/cities/ | F88: 1. Открыто приложение Postman 2. Используется тестовый стенд pl.rassokha.pro:8000/api/v1 3.API доступен и авторизация не требуется для POST-запроса | G88: 1.Создать POST запрос на эндпоинт /family_applications_list/cities/ 2. Отправить запрос | H88: 405 Method Not Allowed { "detail": "Метод \"POST\" не разрешен." } | K88: Passed
A89: family_applications_list | B89: API_fml_pplctns_lst_12 | C89: Высокий | D89: Получение списка городов заявок после заведения нового города | E89: Отправить запрос с методом GET https://pl.rassokha.pro:8000/api/v1/family_applications_list/cities/ | F89: 1) Base URL: pl.rassokha.pro:8000/api/v1 2) Создать заявку с городом, которого еще не было в базе: Отправить POST на эндпоинт /application_family/ С телом Json { "first_name": "string", "last_name": "string", "middle_name": "string", "phone": "string", "email": "string($email)", "city": "string", "district": "string", "address": "string", "situation": "string", "accept_confidential_policy": true } где "first_name", "last_name", "middle_name", "city" : поле должно начинаться с буквы и содержать кириллицу, пробел, тире, количество символов от 1 до 200 "phone" : формат ввода номера: <+79104366339>, минимальное количнство символов 1. "email": латиница от 1 до 254 символов "district" : поле может содержать кириллицу, пробел, дефис, от 1 до 200 символов "address": поле может содержать кириллицу, цифры, -, /, запятую, точку, пробел, от 1 до 500 символов "situation": кириллица от 1 до 4000 символов | G89: 1.Создать GET запрос на эндпоинт /family_applications_list/cities/ 2. Отправить запрос | H89: в списке городов есть город из новой заявки 200 ОК [ "string", "string" ] | K89: Passed
A90: family_applications_list | B90: API_fml_pplctns_lst_13 | C90: Высокий | D90: Получение информации о зарегистрированной заявке на получение помощи | E90: Отправить запрос с методом GET https://pl.rassokha.pro:8000/api/v1/family_applications_list/{id}/ | F90: 1. Открыто приложение Postman 2. Используется тестовый стенд pl.rassokha.pro:8000/api/v1 3.API доступен и авторизация не требуется для GET-запроса | G90: Отправить GET запрос на эндпоинт /family_applications_list/{id}/ где {id} = integer, соответствует id зарегистрированной заявке | H90: 200 ОК { "id": integer, "city": "string", "full_name": "string", "status": "string" } id соответствует запрашиваемому id | K90: Passed
A91: family_applications_list | B91: API_fml_pplctns_lst_14 | C91: Высокий | D91: Получение информации о несуществующей заявке на получение помощи | E91: Отправить запрос с методом GET https://pl.rassokha.pro:8000/api/v1/family_applications_list/{id}/ | F91: 1. Открыто приложение Postman 2. Используется тестовый стенд pl.rassokha.pro:8000/api/v1 3.API доступен и авторизация не требуется для GET-запроса | G91: Отправить GET запрос на эндпоинт /family_applications_list/{id}/ где {id} = integer, число превышающее значение ранее зарегистрированных заявок | H91: 404 Not Found { "detail": "No FamilyApplication matches the given query." } | K91: Passed
A92: family_applications_list | B92: API_fml_pplctns_lst_15 | C92: Высокий | D92: Получение информации о зарегистрированной заявке на получение помощи: при передаче id="string" | E92: Отправить запрос с методом GET https://pl.rassokha.pro:8000/api/v1/family_applications_list/{id}/ | F92: 1. Открыто приложение Postman 2. Используется тестовый стенд pl.rassokha.pro:8000/api/v1 3.API доступен и авторизация не требуется для GET-запроса | G92: Отправить GET запрос на эндпоинт /family_applications_list/"id"/ где id = integer, соответствует id зарегистрированной заявке | H92: 404 Not Found { "detail": "Страница не найдена." } | K92: Passed
...

Sheet Баг-репорты swagger
A1: ID | B1: Severity | C1: Priority | D1: Название бага | E1: Описание | F1: Предусловия | G1: Шаги воспроизведения | H1: ОР | I1: ФР | J1: Скринкаст/скриншот | K1: Окружение | L1: Комментарий | M1: Автор
A2: whm_w_hlpd_bg_swg_1 | B2: Стандартный | C2: Высокий | D2: Ошибка при буквенном значении page при запросе на эндпоинт whom_we_helped/ | E2: Отправить запрос с параметром page, имеющим буквенное значение (например, page=abc). | F2: 1.Открыто приложение Postman 2.Ввести адрес тестового стенда: pl.rassokha.pro:8000/api/v1 3.API доступен и авторизация не требуется для GET-запроса | G2: 1. Создать GET запрос на эндпоинт whom_we_helped/ 2. Во вкладке params вставить key: page 3. Во вкладке params вставить value: abc 2.Отправить запрос | H2: 404 Not Found Body ответа: { "detail": "Неправильная страница" } | I2: 404 Not Found Body ответа: { "detail": "Неправильная страница" } | K2: Postman | L2: Баг в документации swagger | M2: Ибрагимова Юлия
A3: whm_w_hlpd_bg_swg_2 | B3: Стандартный | C3: Высокий | D3: Ошибка при спецсимволах в параметре page при запросе на эндпоинт whom_we_helped/ | E3: Отправить запрос с page=+2 | F3: 1.Открыто приложение Postman 2.Ввести адрес тестового стенда: pl.rassokha.pro:8000/api/v1 3.API доступен и авторизация не требуется для GET-запроса | G3: 1. Создать GET запрос на эндпоинт whom_we_helped/ 2. Во вкладке params вставить key: page 3. Во вкладке params вставить value: +2 2.Отправить запрос | H3: 404 Not Found Body ответа: { "detail": "Неправильная страница" } | I3: 404 Not Found Body ответа: { "detail": "Неправильная страница" } | K3: Postman | L3: Баг в документации swagger | M3: Ибрагимова Юлия
A4: whm_w_hlpd_bg_3 | B4: Стандартный | C4: Высокий | D4: Не описан метод OPTIONS при запросе на эндпоинт whom_we_helped/ | E4: Отправить запрос с методом OPTIONS https://pl.rassokha.pro:8000/api/v1/whom_we_helped/ | F4: 1.Открыто приложение Postman 2.Ввести адрес тестового стенда: pl.rassokha.pro:8000/api/v1 3.API доступен и авторизация не требуется для GET-запроса | G4: 1. Создать OPTIONS запрос на эндпоинт whom_we_helped/ 2. Отправить запрос | H4: 405 Method Not Allowed { "detail": "Метод \"OPTIONS\" не разрешен." } | I4: 405 Method Not Allowed { "detail": "Метод \"OPTIONS\" не разрешен." } | K4: Postman | L4: Серая зона, ошибка не описана в документации API | M4: Ибрагимова Юлия
A5: whm_w_hlpd_bg_4 | B5: Высокий | C5: Высокий | D5: Не прописаны в документации API обязательные поля в ответе при запросе на эндпоинт whom_we_helped/ | E5: Проверить, что в ответе присутствуют посты, у которых заполнены все обязательные и необязательные поля (например, id, image_url, title, description,minLength), и их значения соответствуют ожидаемым типам данных | F5: 1.Открыто приложение Postman 2.Ввести адрес тестового стенда: pl.rassokha.pro:8000/api/v1 3.API доступен и авторизация не требуется для GET-запроса | G5: 1. Создать GET запрос на эндпоинт whom_we_helped/ 2. Отправить запрос | H5: Ошибки в структуре ответа нет "Ответ приходит без ошибок 200 ок | I5: Ошибки в структуре ответа нет "Ответ приходит без ошибок 200 ок | K5: Postman | L5: Серая зона, обязательные поля не описаны в документации API | M5: Ибрагимова Юлия
A6: whm_w_hlpd_bg_5 | B6: Высокий | C6: Высокий | D6: Ошибка при обработке записей без изображений при запросе на эндпоинт whom_we_helped/ | E6: Проверить, как система обрабатывает пост, у которого есть текстовое описание, но отсутствует фотография | F6: 1.Открыто приложение Postman 2.Ввести адрес тестового стенда: pl.rassokha.pro:8000/api/v1 3.API доступен и авторизация не требуется для GET-запроса | G6: 1. Создать GET запрос на эндпоинт whom_we_helped/ 2. Отправить запрос | H6: Ошибки в структуре ответа нет "Ответ приходит без ошибок 200 ок | I6: Ответ приходит без ошибок 200 ок | K6: Postman | L6: Серая зона в документации API. На странице "получить помощь" https://pl.rassokha.pro:3001/get-help фотография не является обязательным требованием, поэтому возможность запросить помощь без фотографии должна быть возможной, однако в документации этот момент не прописан | M6: Ибрагимова Юлия
A7: whm_w_hlpd_bg_6 | B7: Высокий | C7: Высокий | D7: Проблемы с кодировкой Unicode символов при запросе на эндпоинт whom_we_helped/ | E7: Проверить, что отчеты, содержащие в описании символы иностранных языков (например, English, 中文), корректно отображаются в ответе API без искажений (проблем с кодировкой). | F7: 1.Открыто приложение Postman 2.Ввести адрес тестового стенда: pl.rassokha.pro:8000/api/v1 3.API доступен и авторизация не требуется для GET-запроса | G7: 1. Создать GET запрос на эндпоинт whom_we_helped/ 2.Отправить запрос | H7: Ошибки в структуре ответа нет "Ответ приходит без ошибок 200 ок | I7: Ошибки в структуре ответа нет "Ответ приходит без ошибок 200 ок | K7: Postman | L7: Серая зона, обязательные поля не описаны в документации API и в документации swagger | M7: Ибрагимова Юлия
A8: whm_w_hlpd_bg_7 | B8: Стандартный | C8: Высокий | D8: Нарушена структура данных элементов results при запросе на эндпоинт whom_we_helped/ | E8: Проверить, что каждый элемент в массиве содержит ожидаемый набор полей | F8: 1.Открыто приложение Postman 2.Ввести адрес тестового стенда: pl.rassokha.pro:8000/api/v1 3.API доступен и авторизация не требуется для GET-запроса | G8: 1. Создать GET запрос на эндпоинт whom_we_helped/ 2.Отправить запрос | H8: Ошибки в структуре ответа нет Ответ приходит без ошибок 200 ок | I8: Ответ приходит без ошибок 200 ок | K8: Postman | L8: Серая зона, обязательные поля не описаны в документации API | M8: Ибрагимова Юлия
A9: whm_w_hlpd_bg_8 | B9: Блокирующий | C9: Высокий | D9: Несоответствие результатов для page=1 и запроса без page при запросе на эндпоинт whom_we_helped/ | E9: Убедиться, что запросы /api/v1/whom_we_helped/ и /api/v1/whom_we_helped/?page=1 возвращают идентичный результат | F9: "1.Открыто приложение Postman 2.Ввести адрес тестового стенда: pl.rassokha.pro:8000/api/v1 3.API доступен и авторизация не требуется для GET-запроса" | G9: 1. Отправить GET /api/v1/whom_we_helped/ 2. Отправить GET /api/v1/whom_we_helped/?page=1 3. Сравнить ответы | H9: Ошибки в структуре ответа нет "Ответ приходит без ошибок 200 ок | I9: Ответ приходит без ошибок 200 ок { "current_page": 1, "total_objects": 0, "next_page": null, "previous_page": null, "result": [] } | K9: Postman | L9: Невозможно проверить,поскольку в тестовой документации ничего об этом не сказано. Неизвестна идея разработчика, первая страница = 0 или 1 | M9: Ибрагимова Юлия
K10: Postman | L10: Description не передает запрос | M10: Ибрагимова Юлия
A11: whm_w_hlpd_bg_10 | B11: Высокий | C11: Высокий | D11: Ошибка 404 при несуществующих параметрах при запросе на эндпоинт whom_we_helped/ | E11: Отправить запрос с параметром, который не описан в API (например, ?unsupported_param=value) | F11: 1.Открыто приложение Postman 2.Ввести адрес тестового стенда: pl.rassokha.pro:8000/api/v1 3.API доступен и авторизация не требуется для GET-запроса | G11: 1. Создать GET запрос на эндпоинт whom_we_helped/ 2. Во вкладке params вставить key: page 3. Во вкладке params вставить value: ?unsupported_param 2.Отправить запрос | H11: 404 Not Found Body ответа: { "detail": "Неправильная страница" } | I11: 404 Not Found Body ответа: { "detail": "Неправильная страница" } | K11: Postman | L11: Серая зона нет описаня в документации API | M11: Ибрагимова Юлия
A12: API_qstn_pplctn_bg_1 | B12: Стандартный | C12: Низкий | D12: Отрицательный ответ 405 Method Not Allowed не прописан в в документации swagger при попытке проверки запроса с неверным HTTP-методом GET при запросе на эндпоинт /question_application/ | F12: 1.Открыто приложение Postman 2.Ввести адрес тестового стенда: pl.rassokha.pro:8000/api/v1 3.API доступен и авторизация не требуется для GET-запроса | G12: 1. Создать GET-запрос с на эндпоинт /question_application/ 2.Ввести в body { "first_name": "Маша", "last_name": "Машковна", "middle_name": "Михайловна", "phone": "+79165678098", "email": "user@yandex.com", "city": "Москва", "question": "Как долго отправляются товары?", "accept_confidential_policy": true } 3. Выбрать формат json 4. Отправить запрос | H12: 405 Method Not Allowed { "detail": "Метод \"GET\" не разрешен." } | I12: 405 Method Not Allowed { "detail": "Метод \"GET\" не разрешен." } | K12: Postman | L12: Отрицательный ответ не прописан в документации swagger | M12: Ибрагимова Юлия
A13: API_qstn_pplctn_bg_2 | B13: Стандартный | C13: Низкий | D13: Отрицательный ответ 405 Method Not Allowed не прописан в в документации swagger при попытке проверки запроса с неверным HTTP-методом PUT при запросе на эндпоинт /question_application/ | F13: 1.Открыто приложение Postman 2.Ввести адрес тестового стенда: pl.rassokha.pro:8000/api/v1 3.API доступен и авторизация не требуется для PUT-запроса | G13: 1. Создать PUT-запрос с на эндпоинт /question_application/ 2.Ввести в body { "first_name": "Маша", "last_name": "Машковна", "middle_name": "Михайловна", "phone": "+79165678098", "email": "user@yandex.com", "city": "Москва", "question": "Как долго отправляются товары?", "accept_confidential_policy": true } 3. Выбрать формат json 4. Отправить запрос | H13: 405 Method Not Allowed { "detail": "Метод \"PUT\" не разрешен." } | I13: 405 Method Not Allowed { "detail": "Метод \"PUT\" не разрешен." } | K13: Postman | L13: Отрицательный ответ не прописан в документации swagger | M13: Ибрагимова Юлия
A14: API_qstn_pplctn_bg_3 | B14: Стандартный | C14: Низкий | D14: Отрицательный ответ 405 Method Not Allowed не прописан в в документации swagger при попытке проверки запроса с неверным HTTP-методом PATCH при запросе на эндпоинт /question_application/ | F14: 1.Открыто приложение Postman 2.Ввести адрес тестового стенда: pl.rassokha.pro:8000/api/v1 3.API доступен и авторизация не требуется для PATCH-запроса | G14: 1. Создать PATCH-запрос с на эндпоинт /question_application/ 2.Ввести в body { "first_name": "Маша", "last_name": "Машковна", "middle_name": "Михайловна", "phone": "+79165678098", "email": "user@yandex.com", "city": "Москва", "question": "Как долго отправляются товары?", "accept_confidential_policy": true } 3. Выбрать формат json 4. Отправить запрос | H14: 405 Method Not Allowed { "detail": "Метод \"PATCH\" не разрешен." } | I14: 405 Method Not Allowed { "detail": "Метод \"PATCH\" не разрешен." } | K14: Postman | L14: Отрицательный ответ не прописан в документации swagger | M14: Ибрагимова Юлия
A15: API_qstn_pplctn_bg_4 | B15: Стандартный | C15: Низкий | D15: Отрицательный ответ 405 Method Not Allowed не прописан в в документации swagger при попытке проверки запроса с неверным HTTP-методом DELETE при запросе на эндпоинт /question_application/ | F15: 1.Открыто приложение Postman 2.Ввести адрес тестового стенда: pl.rassokha.pro:8000/api/v1 3.API доступен и авторизация не требуется для DELETE-запроса | G15: 1. Создать DELETE-запрос с на эндпоинт /question_application/ 2.Ввести в body { "first_name": "Маша", "last_name": "Машковна", "middle_name": "Михайловна", "phone": "+79165678098", "email": "user@yandex.com", "city": "Москва", "question": "Как долго отправляются товары?", "accept_confidential_policy": true } 3. Выбрать формат json 4. Отправить запрос | H15: 405 Method Not Allowed { "detail": "Метод \"DELETE\" не разрешен." } | I15: 405 Method Not Allowed { "detail": "Метод \"DELETE\" не разрешен." } | K15: Postman | L15: Отрицательный ответ не прописан в документации swagger | M15: Ибрагимова Юлия
A16: API_qstn_pplctn_bg_5 | B16: Стандартный | C16: Средний | D16: Невозможно проверить запрос с неверным HTTP-методом HEAD при запросе на эндпоинт /question_application/ в postman | F16: 1.Открыто приложение Postman 2.Ввести адрес тестового стенда: pl.rassokha.pro:8000/api/v1 3.API доступен и авторизация не требуется для HEAD-запроса | G16: 1. Создать HEAD-запрос с на эндпоинт /question_application/ 2.Ввести в body { "first_name": "Маша", "last_name": "Машковна", "middle_name": "Михайловна", "phone": "+79165678098", "email": "user@yandex.com", "city": "Москва", "question": "Как долго отправляются товары?", "accept_confidential_policy": true } 3. Выбрать формат json 4. Отправить запрос | H16: 405 Method Not Allowed { "detail": "Метод \"HEAD\" не разрешен." } | I16: Ответа нет "Cloud Agent Error:Unable to reach the Cloud Agent. Try later or select a different agent." | J16: 2025-11-09_13-14-29.png | K16: Postman | M16: Ибрагимова Юлия
A17: API_qstn_pplctn_bg_6 | B17: Стандартный | C17: Низкий | D17: Отрицательный ответ 405 Method Not Allowed не прописан в в документации swagger при попытке проверки запроса с неверным HTTP-методом OPTIONS при запросе на эндпоинт /question_application/ | F17: 1.Открыто приложение Postman 2.Ввести адрес тестового стенда: pl.rassokha.pro:8000/api/v1 3.API доступен и авторизация не требуется для PUT-запроса | G17: 1. Создать OPTIONS-запрос с на эндпоинт /question_application/ 2.Ввести в body { "first_name": "Маша", "last_name": "Машковна", "middle_name": "Михайловна", "phone": "+79165678098", "email": "user@yandex.com", "city": "Москва", "question": "Как долго отправляются товары?", "accept_confidential_policy": true } 3. Выбрать формат json 4. Отправить запрос | H17: { "detail": "Метод \"OPTIONS\" не разрешен." } | I17: { "detail": "Метод \"OPTIONS\" не разрешен." } | K17: Postman | L17: Отрицательный ответ не прописан в документации swagger | M17: Ибрагимова Юлия
A18: API_fml_pplctns_lst_bg_3 | B18: Высокий | C18: Высокий | D18: в документации нет требований к ответу для GET /family_applications_list/cities/ | F18: ссылка на swagger: https://pl.rassokha.pro:8000/swagger/ | G18: 1) пройти по ссылке: https://pl.rassokha.pro:8000/swagger/ 2) выполнить GET запрос на эндпоинт /family_applications_list/cities/ | H18: в графе Responses указаны требования для список городов, указанных при регистрации заявки на оказание помощи в алфавитном порядке 200 ОК [ "string", "string" ] | I18: указан формат ответа для GET /family_applications_list/ 200 ОК { "count": 0, "next": "string", "previous": "string", "results": [ { "id": 0, "city": "string", "full_name": "string", "status": "new_in" } ] } | J18: API_fml_pplctns_lst_bg_3.png | K18: Swagger | M18: Раскошная Анастасия
A19: API_dntn_bg1 | B19: Высокий | C19: Высокий | D19: Запросы к эндпоинту /donation/ запрещены | E19: Отправка POST запроса возвращает 403 Forbidden. Невозможно проверить функционал | F19: 1. Открыто приложение Postman 2. Используется тестовый стенд pl.rassokha.pro:8000/api/v1 | G19: 1. Создать POST запрос на эндпоинт /donation/ 2. В тело запроса вставить: { "id": "string", "created_at": "string", "amount": { "additionalProp1": "string", "additionalProp2": "string", "additionalProp3": "string" }, "metadata": { "additionalProp1": "string", "additionalProp2": "string", "additionalProp3": "string" }, "status": "pending", "description": "string", "value": "string", "family_request": [ 0 ], "first_name": "string", "payment_method": "string" } 3.Отправить запрос | H19: Возвращается код 200 Created Возвращаются заголовки: { "Vary": "Accept, Cookie", "Allow": "POST, OPTIONS", "X-Frame-Options": "SAMEORIGIN", "Content-Length": "0", "X-Content-Type-Options": "nosniff", "Referrer-Policy": "same-origin", "Cross-Origin-Opener-Policy": "same-origin" } | I19: Возвращается код 403 Forbidden Приходит ответ с телом: <html> <head> <title>403 Forbidden</title> </head> <body> <center> <h1>403 Forbidden</h1> </center> <hr> <center>nginx</center> </body> </html> | K19: Postman | M19: Тимофей Каналин
A20: API_blg_bg1 | B20: Стандартный | C20: Средний | D20: В документации в теле ответа нет к эндпоинту /blog/ нет элемента "current" | F20: ссылка на swagger: https://pl.rassokha.pro:8000/swagger/ | G20: Отправить GET запрос на на эндпоинт /blog/ | H20: 200 ОК { "current": integer "count": integer, "next": "string", "previous": "string", "results": [ { "id": 0, "title": "string", "image": "string", "created_at": "string($date-time)", "link": "string" } ] } где "current": 1 | I20: в документации нет элемента "current" { "count": integer, "next": "string", "previous": "string", "results": [ { "id": integer, "title": "string", "image": "string", "created_at": "string($date-time)", "link": "string" } ] } | J20: API_blg_1.png | K20: Swagger | M20: Раскошная Анастасия
K21: Swagger | M21: Ибрагимова Юлия
K22: Postman | M22: Ибрагимова Юлия
K23: Postman | M23: Ибрагимова Юлия
K24: Postman | M24: Ибрагимова Юлия
K25: Postman | M25: Ибрагимова Юлия
K26: Postman | M26: Ибрагимова Юлия
K27: Postman | M27: Ибрагимова Юлия
J28: API.png | K28: Postman | M28: Гемуев Кирилл
A29: API_fml_rqst_bg1 | B29: Критический | C29: Высокий | D29: В документации не описанн POST запрос на эндпоинт family_request/{id}/comments/ | E29: В документации не описанн POST запрос на эндпоинт family_request/{id}/comments/ Поле для коментарьев присутствует на фронтенде | F29: 1. Открыто приложение Postman 2. Используется тестовый стенд pl.rassokha.pro:8000/api/v1 3.API доступен и авторизация не требуется для POST-запроса | G29: 1. Создать POST запрос на эндпоинт family_request/{id}/comments/ где {id} - существующий запрос 2. Отправить запрос | H29: 405 Method Not Allowed { "detail": "Метод \"POST\" не разрешен." } | I29: 400 Error: Bad Request { "name": [ "Обязательное поле." ], "email": [ "Обязательное поле." ], "text": [ "Обязательное поле." ], "accept_confidential_policy": [ "Обязательное поле." ] } | J29: family_request.png | K29: Postman | M29: Гемуев Кирилл
A30: API_they_nd_hlp_bg1 | B30: Стандартный | C30: Средний | D30: В документации GET /they_need_help_too/{id}/ неверный тип данных для id | E30: Тип данных id должен быть integer | F30: 1. Открыто приложение Postman 2. Используется тестовый стенд pl.rassokha.pro:8000/api/v1 | G30: 1. Создать POST запрос на эндпоинт /they_need_help_too/{id}/ где {id} - существующий идентификатор семьи 2. Отправить запрос | H30: Возвращается код 200 OK Тело ответа: [ { "id": integer, "family_name": "string", "image": "string" } ] | I30: 405 Method Not Allowed { "detail": "Метод не поддерживается." } | K30: Postman | L30: ОР и ФР относятся к функциональному багу (см QA_Pomogi_2_39_Тестовая документация) | M30: Тимофей Каналин

Sheet Баг-репорты API
A1: ID | B1: Severity | C1: Priority | D1: Название бага | E1: Описание | F1: Предусловия | G1: Шаги воспроизведения | H1: ОР | I1: ФР | J1: Скринкаст/скриншот | K1: Окружение | L1: Комментарий | M1: Автор
J2: video_report_bg1.png | K2: Postman | L2: Не действительный баг | M2: Гемуев Кирилл
J3: they_need_help_too_bg1.png | K3: Postman | M3: Гемуев Кирилл
J4: social_links_bg1.png | K4: Postman | L4: Не действительный баг | M4: Гемуев Кирилл
J5: faq_bg1.png | K5: Postman | L5: Не действительный баг | M5: Гемуев Кирилл
A6: API_fml_pplctns_lst_bg_1 | B6: Высокий | C6: Высокий | D6: 200 ОК при создании GET запроса на эндпоинт /family_applications_list/ с параметром "limit" и "offset" = дробь | F6: Base URL: pl.rassokha.pro:8000/api/v1 | G6: 1. Создать GET запрос на эндпоинт /family_applications_list/ 2. Во вкладке Params ввести: key: "limit", value: 2.2 key: "offset", value: 2.2 3. Отправить запрос | H6: 400 Bad Request | I6: Список из 10 первых оформленных заявок 200 Ок { "count": integer, "next": "string($uri)", "previous": "string($uri)", "results": [ { "id": integer, "city": "string", "full_name": "string", "status": "string" } ] } | J6: API_fml_pplctns_lst_1.png | K6: Postman | L6: в документации нет информации о формате ошибки | M6: Раскошная Анастасия
A7: API_fml_pplctns_lst_bg_2 | B7: Высокий | C7: Высокий | D7: 200 ОК при создании GET запроса на эндпоинт /family_applications_list/ с параметром "limit" и "offset" = "string" | F7: Base URL: pl.rassokha.pro:8000/api/v1 | G7: 1. Создать GET запрос на эндпоинт /family_applications_list/ 2. Во вкладке Params ввести: key: "limit", value: "5" key: "offset", value: "5" 3. Отправить запрос | H7: 400 Bad Request | I7: Список из 10 первых оформленных заявок 200 Ок { "count": integer, "next": "string($uri)", "previous": "string($uri)", "results": [ { "id": integer, "city": "string", "full_name": "string", "status": "string" } ] } | J7: API_fml_pplctns_lst_2.png | K7: Postman | L7: в документации нет информации о формате ошибки | M7: Раскошная Анастасия
A8: API | B8: Высокий | C8: Высокий | D8: Ответ 200 при запросе неверным HTTP-методом | E8: При отправке запроса на любой эдпоинт неверным HTTP-методом можно получить ответ 200, если в конце адреса не ставить "/" | F8: 1. Открыто приложение Postman 2. Используется тестовый стенд pl.rassokha.pro:8000/api/v1 3.API доступен и авторизация не требуется для POST-запроса | G8: 1. Создать GET запрос на эндпоинт/helped_online 2. Отправить запрос | H8: 405 Method Not Allowed { "detail": "Метод \"POST\" не разрешен." } | I8: 200 Ок [ { "count": integer, "description": "string" } ] | K8: Postman | M8: Гемуев Кирилл
A9: API_blg_bg2 | B9: Высокий | C9: Высокий | D9: Ответ 404 при создании GET запроса на эндпоинт /blog/ с параметром "page" = "string" | F9: Base URL: pl.rassokha.pro:8000/api/v1 | G9: 1. Создать GET запрос на эндпоинт /blog/ 2. Во вкладке Params ввести: key: "page", value: "2" 3. Отправить запрос | H9: 400 Bad Request | I9: 404 Not Found { "detail": "Неправильная страница" } | J9: API_blg_bg2.png | K9: Postman | M9: Раскошная Анастасия
A10: API_blg_bg3 | B10: Высокий | C10: Высокий | D10: Ответ 404 при создании GET запроса на эндпоинт /blog/ с параметром "page" = null | F10: Base URL: pl.rassokha.pro:8000/api/v1 | G10: 1. Создать GET запрос на эндпоинт /blog/ 2. Во вкладке Params ввести: key: "page", value: null 3. Отправить запрос | H10: Список постов в блоге: первая страница, 8 постов, начиная с последнее опубликованного. 200 ОК { "current": integer, "count": integer, "next": "string", "previous": null, "results": [ { "id": integer, "title": "string", "image": "string", "created_at": "string($date-time)", "link": "string" } ] } где "current": 1 | I10: 404 Not Found { "detail": "Неправильная страница" } | J10: API_blg_bg3.png | K10: Postman | M10: Раскошная Анастасия
A11: API_blg_bg4 | B11: Стандартный | C11: Средний | D11: В теле ответа нет времени создания блога при создании GET запроса на эндпоинт /blog/ | F11: Base URL: pl.rassokha.pro:8000/api/v1 | G11: Отправить GET запрос на эндпоинт /blog/ | H11: Список постов в блоге: первая страница, 8 постов, начиная с последнее опубликованного. 200 ОК { "current": integer, "count": integer, "next": "string", "previous": null, "results": [ { "id": integer, "title": "string", "image": "string", "created_at": "string($date-time)", "link": "string" } ] } где "current": 1, "created_at": имеет вид "2025-11-11T17:54:58.387Z" | I11: Список постов в блоге: первая страница, 8 постов, начиная с последнее опубликованного. 200 ОК { "current": integer, "count": integer, "next": "string", "previous": null, "results": [ { "id": integer, "title": "string", "image": "string", "created_at": "string($date-time)", "link": "string" } ] } где "current": 1, "created_at": имеет вид "20.06.2025" | J11: API_blg_bg4.png | K11: Postman | M11: Раскошная Анастасия
A12: API_blg_bg5 | B12: Стандартный | C12: Средний | D12: В теле ответа нет времени создания блога при создании GET запроса на эндпоинт /blog/ {id} | F12: Base URL: pl.rassokha.pro:8000/api/v1 | G12: Отправить GET запрос на эндпоинт /blog/{id}/ где id=integer, существующего блога | H12: 200 OK { "count": integer, "next": "string", "previous": "string", "results": [ { "id": integer, "title": "string", "image": "string", "created_at": "string($date-time)", "link": "string" } ] } где id соответствует заданному, "created_at": имеет вид "2025-11-11T22:17:48.433Z" | I12: 200 OK { "count": integer, "next": "string", "previous": "string", "results": [ { "id": integer, "title": "string", "image": "string", "created_at": "string($date-time)", "link": "string" } ] } где id соответствует заданному, "created_at": имеет вид "14.06.2025" | K12: Postman | M12: Раскошная Анастасия
I13: 200 OK { "count": integer, "next": "string", "previous": "string", "results": [ { "id": integer, "title": "string", "image": "string", "created_at": "string($date-time)", "link": "string" } ] } где id соответствует заданному, "created_at": имеет вид "14.06.2025" | J13: API_blg_bg6.png | K13: Postman | L13: Не действительный баг | M13: Раскошная Анастасия
A14: API_dntn_bg_1 | B14: Высокий | C14: Высокий | D14: Отправка POST запроса на эндпоинт /donation/ запрещена | F14: 1. Открыто приложение Postman 2. Используется тестовый стенд pl.rassokha.pro:8000/api/v1 | G14: 1. Создать POST запрос на эндпоинт /donation/ 2. В тело запроса вставить: { "id": "string", "created_at": "string", "amount": { "additionalProp1": "string", "additionalProp2": "string", "additionalProp3": "string" }, "metadata": { "additionalProp1": "string", "additionalProp2": "string", "additionalProp3": "string" }, "status": "pending", "description": "string", "value": "string($decimal)", "family_request": [ 0 ], "first_name": "string", "payment_method": "string" } 3.Отправить запрос | H14: Возвращается код 200 Created Возвращаются заголовки: { "Vary": "Accept, Cookie", "Allow": "POST, OPTIONS", "X-Frame-Options": "SAMEORIGIN", "Content-Length": "0", "X-Content-Type-Options": "nosniff", "Referrer-Policy": "same-origin", "Cross-Origin-Opener-Policy": "same-origin" } | I14: Возвращается код 403 Forbidden | K14: Postman | M14: Тимофей Каналин

Sheet Чек-лист САЙТ
A1: Vjlekm | B1: ID | C1: Приоритет | D1: Описание проверки | E1: Ссылка на баг-репорт | F1: Комментарий | G1: Статус проверки ОС: Разрешение: Браузер: Chrome 141.0.7390.123 | H1: Статус проверки ОС: macOS Tahoe 26.0.1 Разрешение: 3456 x 2234 Браузер: Chrome 142.0.7444.135 | I1: Статус проверки ОС: Windows 11 Разрешение: 2560х1600 Браузер: Яндекс. 25.8.5.890 | J1: Статус проверки ОС: Windows 10 Pro 22H2 Разрешение: 2560x1080 Браузер: Яндекс. 25.10.0.2474 | K1: Статус проверки ОС: Windows 10 Разрешение: 1980x1080 Браузер: Opera 123.0.5669.23 | L1: Статус проверки ОС: Windows 11 Pro Разрешение: 1920х1080 Браузер: Opera 123.0.5669.47 | M1: Статус проверки ОС: Разрешение: Браузер: Edge 142.0.3595.53 | N1: Статус проверки ОС: Windows 10 Разрешение: 1920х1080 Браузер: Edge 142.0.3595.65
A2: Главная страница | B2: hm_pg_2 | C2: Критичный | D2: На страницу "Главная" можно попасть введя ссылку в браузер https://pl.rassokha.pro:3001 | H2: Passed | I2: Passed | L2: Passed | N2: Passed
A3: Главная страница | B3: hm_pg_3 | C3: Критичный | D3: При первом посещении страницы в нижней части экрана появляется текст: «Мы используем файлы cookie для анализа трафика и улучшения вашего опыта. Некоторые cookie необходимы для работы сайта. Подробнее в нашей Политике использования cookie.». В этом сообщении есть 2 кнопки зелёного цвета: «Отклонить» и «Принять все». | H3: Passed | I3: Passed | L3: Passed | N3: Passed
A4: Главная страница | B4: hm_pg_4 | C4: Низкий | D4: Отображение блока с заголовком "Вы помогли этим детям!" в верхней левой части экрана. | H4: Passed | I4: Passed | L4: Passed | N4: Passed
A5: Главная страница | B5: hm_pg_5 | C5: Низкий | D5: Используемый цвет фона для блока "Вы помогли этим детям! " #EFB46D | F5: А разве не подложка будет с элементами на ней? В макете есть галочки в кружочка на подложке цвета #EFB46D, а фон белый уже как все страницы у блока | H5: Passed | I5: Passed | L5: Passed | N5: Passed
A6: Главная страница | B6: hm_pg_6 | C6: Средний | D6: Заголовок "Вы помогли этим детям! " расположен в левой части экрана | H6: Passed | I6: Passed | L6: Passed | N6: Passed
A7: Главная страница | B7: hm_pg_7 | C7: Низкий | D7: Заголовок блока "Вы помогли этим детям! " выделен крупным шрифтом "ХL" | H7: Passed | I7: Passed | L7: Passed | N7: Passed
A8: Главная страница | B8: hm_pg_8 | C8: Низкий | D8: Используемый шрифт текста "Вы помогли этим детям! ", "Neucha" | H8: Passed | I8: Passed | L8: Passed | N8: Passed
A9: Главная страница | B9: hm_pg_9 | C9: Низкий | D9: Используемый цвет шрифта заголовка "Вы помогли этим детям! " на макете и на сайте #FFFFFF | H9: Passed | I9: Passed | L9: Passed | N9: Passed
A10: Главная страница | B10: hm_pg_10 | C10: Низкий | D10: Под заголовком "Вы помогли этим детям! " расположены блоки "видео" | H10: Passed | I10: Passed | L10: Passed | N10: Passed
A11: Главная страница | B11: hm_pg_11 | C11: Низкий | D11: Наличие длительности в правом нижнем углу. | E11: hm_pg_bg_1 | H11: Failed | I11: Failed | L11: Failed | N11: Failed
A12: Главная страница | B12: hm_pg_12 | C12: Низкий | D12: Используемый цвет цифр длительности "видео", "0:08" #FFFFFF | E12: hm_pg_bg_1 | H12: Blocked | I12: Blocked | L12: Blocked | N12: Blocked
A13: Главная страница | B13: hm_pg_13 | C13: Низкий | D13: Форма блока (прямоугольная с закруглёнными краями). | H13: Passed | I13: Passed | L13: Passed | N13: Passed
A14: Главная страница | B14: hm_pg_14 | C14: Низкий | D14: Ниже под "видео" расположен заголовок с описанием | H14: Passed | I14: Passed | L14: Passed | N14: Passed
A15: Главная страница | B15: hm_pg_15 | C15: Низкий | D15: Размер текста : s медиум | H15: Passed | I15: Passed | L15: Passed | N15: Passed
A16: Главная страница | B16: hm_pg_16 | C16: Низкий | D16: Цвет текста: #267067 | H16: Passed | I16: Passed | L16: Passed | N16: Passed
A17: Главная страница | B17: hm_pg_17 | C17: Низкий | D17: Шрифт текста "Montserrat" | H17: Passed | I17: Passed | L17: Passed | N17: Passed
A18: Главная страница | B18: hm_pg_18 | C18: Низкий | D18: Ниже описанием подарков, расположены "просмотры" "18 просмотров • 3 месяца назад" | H18: Passed | I18: Passed | L18: Passed | N18: Passed
A19: Главная страница | B19: hm_pg_19 | C19: Низкий | D19: Заголовок текста "18 просмотров • 3 месяца назад" выделен крупным шрифтом "ххs" | H19: Passed | I19: Passed | L19: Passed | N19: Passed
A20: Главная страница | B20: hm_pg_20 | C20: Низкий | D20: Используемый цвет шрифта "18 просмотров • 3 месяца назад" # 727271 | H20: Passed | I20: Passed | L20: Passed | N20: Passed
A21: Главная страница | B21: hm_pg_21 | C21: Низкий | D21: Используемый шрифт текста "18 просмотров • 3 месяца назад" , "Montserrat" | H21: Passed | I21: Passed | L21: Passed | N21: Passed
A22: Главная страница | B22: hm_pg_22 | C22: Высокий | D22: При клике на "видео" открывается новая вкладка в браузере "Благотворительный фонд "Помоги Лично" "ВКонтакте". | H22: Passed | I22: Passed | L22: Passed | N22: Passed
A23: Главная страница | B23: hm_pg_23 | C23: Средний | D23: Проверки аналогичные для каждого последующего блока с описанием "видео" | H23: Passed | I23: Passed | L23: Passed | N23: Passed
A24: Главная страница | B24: hm_pg_24 | C24: Средний | D24: В правом верхнем углу над блоком фото "видео" расположены иконки стрелки "<", ">" | H24: Passed | I24: Passed | L24: Passed | N24: Passed
... A35: Главная страница | B35: hm_pg_38 | C35: Низкий | D35: Ниже под блоком "Вы помогли этим детям! " расположен блок с заголовком "Нужна помощь!" | H35: Passed | I35: Passed | L35: Passed | N35: Passed
A36: Главная страница | B36: hm_pg_39 | C36: Средний | D36: Блок "Нужна помощь!" состоит из следующих элементов: фон "подложка", блок из карточек "семья", фото, стрелки, лого, кнопка, заголовки текста | E36: QA_Pomogi_2_39_Тестовая документация | H36: Passed | I36: Passed | L36: Passed | N36: Failed
A37: Главная страница | B37: hm_pg_41 | C37: Низкий | D37: Заголовок блока "Нужна помощь!" выделен крупным шрифтом "ХL" | H37: Passed | I37: Passed | L37: Passed | N37: Passed
A38: Главная страница | B38: hm_pg_42 | C38: Низкий | D38: Используемый шрифт текста "Нужна помощь!", "Neucha" | H38: Passed | I38: Passed | L38: Passed | N38: Passed
A39: Главная страница | B39: hm_pg_43 | C39: Низкий | D39: Используемый цвет шрифта заголовка "Нужна помощь!" на макете и на сайте #FFFFFF | H39: Passed | I39: Passed | L39: Passed | N39: Passed
A40: Главная страница | B40: hm_pg_44 | C40: Низкий | D40: Под заголовком "Нужна помощь!" расположена карточка с фото "семья" | H40: Passed | I40: Passed | L40: Passed
A41: Главная страница | B41: hm_pg_45 | C41: Низкий | D41: Карточка имеет прямоугольную форму с закругленными краями | H41: Passed | I41: Passed | L41: Passed | N41: Passed
A42: Главная страница | B42: hm_pg_46 | C42: Низкий | D42: Карточка разделена на 2 цвета, правая часть #FFFFFF цвет левая часть #FFE0BC | H42: Passed | L42: Passed | N42: Passed
A43: Главная страница | B43: hm_pg_47 | C43: Низкий | D43: В верхнем левом углу карточки расположено фото семьи | H43: Passed | I43: Passed | L43: Passed | N43: Passed
A44: Главная страница | B44: hm_pg_48 | C44: Средний | D44: Фото кликабельно, при клике раскрывается по центру экрана (в модальном окне) | H44: Passed | I44: Passed | L44: Passed | N44: Passed
A45: Главная страница | B45: hm_pg_49 | C45: Средний | D45: Нажатие на крестик в правом верхнем углу в модальном окне закрывает фото | H45: Passed | I45: Passed | L45: Passed | N45: Passed
A46: Главная страница | B46: hm_pg_50 | C46: Низкий | D46: По центру фото "семьи" с левой и правой стороны расположены угловые стрелки | F46: Не хватает проверок на стрелки в модальном окне | H46: Passed | I46: Passed | L46: Passed | N46: Passed
A47: Главная страница | B47: hm_pg_51 | C47: Низкий | D47: Используемый цвет стрелки "<", #FFFFFF | H47: Passed | I47: Passed | L47: Passed | N47: Passed
A48: Главная страница | B48: hm_pg_52 | C48: Средний | D48: Угловая стрелка кликабельна "<" имеет 2 состояния "default", "hover" | H48: Passed | I48: Passed | L48: Passed | N48: Passed
A49: Главная страница | B49: hm_pg_53 | C49: Средний | D49: При нажатии на иконку "<" перелистывае фото "семьи" в лево | H49: Passed | I49: Passed | L49: Passed | N49: Passed
A50: Главная страница | B50: hm_pg_54 | C50: Низкий | D50: Аналогичные проверки для уловой стрелки в право ">" | H50: Passed | I50: Passed | L50: Passed | N50: Passed
...

Sheet Баг-репорты САЙТ
A1: ID | B1: Severity | C1: Priority | D1: Название бага | E1: Описание | F1: Предусловия | G1: Шаги воспроизведения | H1: ОР | I1: ФР | J1: Скринкаст/скриншот | K1: Окружение | L1: Комментарий
